## 예외처리(Exception Handling)

#### 예외 처리 구문(`try` - `catch`)
```csharp
try{
    // 실행코드
}
catch(Exception 객체1){
    // 어떤 예외가 발생했을때 처리 코드
}
catch(Exception 객체2){
    // catch문은 여러개가 올 수 있다.
}
...
```

<br />

```csharp
Ex - 기존 예외 발생 코드

namespace ExceptionEx
{   
    class Program
    {
        static void Main(string[] args)
        {
            int[] array = {1,2,3,4,5};
            for(int i = 0; i < 6; i++)
            {
                Console.WriteLine(array[i]);
            }
            Console.WriteLine("프로그램 종료!!");
        }
    }
}
```
```
Output

1
2
3
4
5
Unhandled exception. System.IndexOutOfRangeException: Index was outside the bounds of the array.
   at ExceptionEx.Program.Main(String[] args) in C:\Users\shkim\source\repos\ClassEx\practice1\Program.cs:line 31 

```
- 예외 발생시 실행하던 프로그램이 예외를 출력하며 중지되는 것을 확인할 수 있다. 

- 이때 try - catch 구문을 사용하여 예외를 처리해주면 프로그램이 중지하지 않는다.


<br /> 

```csharp
Ex - Use try-catch

using System.Collections;
namespace ExceptionEx
{   
    class Program
    {
        static void Main(string[] args)
        {
            try
            {
                int[] array = { 1, 2, 3, 4, 5 };
                for (int i = 0; i < 6; i++)
                {
                    Console.WriteLine(array[i]);
                }
            }
            catch (IndexOutOfRangeException e)
            {
                Console.WriteLine($"오류가 발생했습니다. : {e.Message}");
            }
            catch (Exception e)
            {
                Console.WriteLine($"오류가 발생했습니다. : {e.Message}");
            }
           
            Console.WriteLine("프로그램 종료!!");
        }
    }
}
```
```
Output

1
2
3
4
5
오류가 발생했습니다. : Index was outside the bounds of the array.
프로그램 종료!!
```


- 프로그램 종료메세지가 나옴. => 오류는 잡고 프로그램이 중지가 되는 현상이 발생하지 않음. 마지막까지 정상적으로 수행됨.