## 7.0에서 throw문 표현식, finally 절
----------------------------------------------------------------

<br />

#### c# 7.0에서의 throw문의 표현식(Expression)

<br />

```csharp
using System.Collections;

//c# 7.0에서의 throw문의 표현식(Expression)
namespace ExceptionEx
{
    class Program
    {
        static void Main(string[] args)
        {
            try
            {
                int? aa = null;
                int bb = aa ?? throw new ArgumentNullException();
            }
            catch (ArgumentNullException e)
            {
                Console.WriteLine(e.Message);
            }

            try
            {
                int[] arr = {1, 2, 3 };
                int idx = 5;
                int value = arr[idx >= 0 && idx < 4 ? idx : throw new IndexOutOfRangeException()];
                Console.WriteLine(value);
            }
            catch (ArgumentOutOfRangeException e)
            {
                Console.WriteLine(e.Message);
            }
        }
    }
}
```

```
Output

Value cannot be null.
Unhandled exception. System.IndexOutOfRangeException: Index was outside the bounds of the array.
   at ExceptionEx.Program.Main(String[] args) in C:\Users\shkim\source\repos\ClassEx\practice1\Program.cs:line 24
```

- c# 7.0에서의 throw문은 아무래도 삼항연산자와 같이 작성하는 방식인 듯 하다. 
- 기존 예외처리 구문과 비교해서 보도록하자.

<br />

#### try-catch finally 문

<br />

- finally문 : 상위 코드에서 예외가 발생하더라도 반드시 실행되는 절이다. 

- try문 내에서 A코드, B코드, C코드가 있는경우 B에서 예외발생시 C코드는 수행이 안된다. 
    - 만일 C코드가 반드시 실행되어야 하는 코드임에도 실행되지 않는 경우가 있다. C코드의 예로는 Database 및 시스템 리소스 자원 반납 코드 등 .. Database 커넥션 해제 코드의 경우 실행되지 않았을 시 향후 다른 프로그램에서 해당 database에 접속할 수 있는 커넥션 양이 줄어들게 된다. => 결국에는 DB에 접속하지 못하는 경우가 발생할 수 있다 => 서버에 부하가 생김. 

- 이는 finally문을 통해 해결할 수 있다. finally문에 작성해줌으로써 catch문 이후에 반드시 실행되도록 하면 이를 해결할 수 있다.

<br />

###### finally문 없이 catch문 이후에 작성해주면 되지 않나요?
```
catch문이 여러개 있는 경우 여러개의 catch문 다음에 중복된 C와 같은 코드를 계속해서 작성해줘야 하는 번거로움이 생김
따라서 finally문을 마지막에 작성해줌으로써 이를 해결.
```

<br />

#### 사용 예시 코드

<br />

```csharp
using System.Collections;

namespace ExceptionEx
{
    class Program
    {
        static int divideMethod(int a, int b)
        {
            try { 
                return a / b;
            }
            catch(DivideByZeroException e)
            {
                Console.WriteLine("나누기 예외 발생");
                throw e;
            }
        }
        static void Main(string[] args)
        {
            try { 
                Console.WriteLine("a/b 수식에서 a 의 값을 입력하세요 : ");
                string aa = Console.ReadLine();
                int a = Convert.ToInt32(aa);
            
                Console.WriteLine("a/b 수식에서 b 의 값을 입력하세요 : ");
                string bb = Console.ReadLine();
                int b = Convert.ToInt32(bb);

                Console.WriteLine($"{a}/{b} = {divideMethod(a, b)}");

                Console.WriteLine("프로그램 종료"); // finally문이 없는 경우 예외 발생시 이 코드는 실행이 안됨.
            } 
            catch (DivideByZeroException e)
            {
                Console.WriteLine($"에러 : {e.Message}");   
            }
            finally
            {
                Console.WriteLine("프로그램 종료");
            }

        }
    }
}
```

```
Input

a/b 수식에서 a 의 값을 입력하세요 :
10
a/b 수식에서 b 의 값을 입력하세요 :
0

Output
나누기 예외 발생
에러 : Attempted to divide by zero.
프로그램 종료
```
